Workbook

Sheet 📱 Structured — App 1
B1: App 1 Evaluation (Characteristics 1–8)
B2: 50 min | Individual — use your own device | Min. 3 observations per characteristic
B4: APP 1 METADATA
B5: App 1 Name | C5: youtube music
B6: Version Number | C6: 9.16.4
B7: Device Model | C7: IPHONE 16e
B8: OS Version | C8: 26.3.1
B9: Evaluation Date | C9: 26-4-26
B10: Start Time | C10: 12:55PM
B12: B.2 CHARACTERISTIC 1 — Functional Suitability (Weight: 15%)
B13: Feature / Use Case to Test | C13: How to Test | D13: Pass / Fail / Partial | E13: Notes | F13: Evidence Screenshot
B14: Primary core function | C14: Search and play a song | D14: pass | E14: Songs play correctly, but ads appear between tracks | F14: =_xlfn.DISPIMG("ID_0838DCF26C58473FAE79CC97E4C64B49",1) -> =DISPIMG("ID_0838DCF26C58473FAE79CC97E4C64B49",1)
B15: Secondary feature 1 | C15: Create playlist and add songs | D15: Pass | E15: Playlist works normally, easy to add/remove songs | F15: =_xlfn.DISPIMG("ID_E907978E1386440DA5D15A179BE61F5A",1) -> =DISPIMG("ID_E907978E1386440DA5D15A179BE61F5A",1)
B16: Secondary feature 2 | C16: Try offline listening | D16: Fail | E16: Download feature not available in free version | F16: =_xlfn.DISPIMG("ID_E78696EF51BF47799512B134E23D84FB",1) -> =DISPIMG("ID_E78696EF51BF47799512B134E23D84FB",1)
B17: Error handling | C17: Search empty or wrong song name | D17: Pass | E17: Shows suggestions or “no results found | F17: =_xlfn.DISPIMG("ID_F4DAA453328E49649495E5A263F320AD",1) -> =DISPIMG("ID_F4DAA453328E49649495E5A263F320AD",1)
B18: Edge case | C18: Turn off internet while playing | D18: Partial | E18: Music stops unless already buffered; no offline access | F18: =_xlfn.DISPIMG("ID_2C1C922912864810856333CB3E946382",1) -> =DISPIMG("ID_2C1C922912864810856333CB3E946382",1)
B19: CHARACTERISTIC 1 RATING (1–5): | E19: 4 | F19: Justification:
B21: B.3 CHARACTERISTIC 2 — Performance Efficiency (Weight: 12%)
B22: Measurement | C22: Test Method | D22: Your Result | E22: Target (Rating 4+) | F22: Notes
B23: Cold start time | C23: Open app :fully loaded | D23: 3 sec | E23: < 3 seconds | F23: load sucessfully
B24: Key operation 1 (primary) | C24: Search and play song | D24: 2 sec | E24: < 1 second | F24: works properly
B25: Key operation 2 (secondary) | C25: Navigate playlist | D25: 2 sec | E25: < 2 seconds | F25: Smooth scrolling and loading
B26: Battery drain | C26: Device Settings > Battery: % used in 10 min active use | D26: 2 percent | E26: < 3% | F26: Video-based system uses slightly more battery
B27: Slow network | C27: Switch to 4G only / poor signal — time key operation | D27: 4 sec | E27: < 5 seconds | F27: slow
B28: Data usage | C28: Device Settings > Data: MB used in 10 min active use | D28: 10 mb | E28: < 10 MB | F28: Depends on quality settings
B29: CHARACTERISTIC 2 RATING (1–5): | E29: 4 | F29: Justification:
B31: B.4 CHARACTERISTIC 3 — Compatibility (Weight: 10%)
B32: Compatibility Check | C32: What to Look For | D32: Result | E32: Evidence / Screenshot | F32: Notes
B33: Min OS version | C33: Check Play Store / App Store listing for minimum supported OS | D33: pass | E33: =_xlfn.DISPIMG("ID_BB332484863346A9B3890BD0B4883639",1) -> =DISPIMG("ID_BB332484863346A9B3890BD0B4883639",1) | F33: iOs16.0
B34: Platform availability | C34: List all platforms: Android, iOS, Windows, macOS, Web, Linux | D34: pass | E34: =_xlfn.DISPIMG("ID_5808FA69B6DA4B868348953FE8251519",1) -> =DISPIMG("ID_5808FA69B6DA4B868348953FE8251519",1) | F34: available on all
B35: Cross-device sync | C35: Log in on a 2nd device — do data & settings appear? | D35: pass | F35: works with same account
B36: Content sharing (in) | C36: Can you share content FROM other apps INTO this app? | D36: partial | F36: Limited ability to import playlists
B37: Content sharing (out) | C37: Can you share content FROM this app to 3+ other apps? | D37: pass | E37: =_xlfn.DISPIMG("ID_8A77A4E9597C4B50B80F6F42B71FEB0B",1) -> =DISPIMG("ID_8A77A4E9597C4B50B80F6F42B71FEB0B",1) | F37: Can share links easily (WhatsApp, etc.)
B38: Dark mode support | C38: Does the app respect your OS dark mode / accessibility settings? | D38: pass | F38: Fully supported
B39: OS version compat. | C39: Any features broken on your specific OS version? | D39: pass | F39: No major issues observed
B40: CHARACTERISTIC 3 RATING (1–5): | E40: 4 | F40: Justification:
B42: B.5 CHARACTERISTIC 4 — Usability (Weight: 15%)
B43: Task | C43: Task Description | D43: Time (sec) | E43: Errors Made | F43: Completed?
B44: Task 1 | C44: Change setting (theme/notifications) | D44: 15 sec | E44: 0 | F44: yes
B45: Task 2 | C45: Play a song for first time | D45: 12 sec | E45: 0 | F45: yes
...

Sheet 📋 Session Setup
B1: SQE Lab Session 2 — ISO 25010 Quality Attribute Analysis
B2: Software Quality Engineering | Lab Manual | Engr. Asim Javaid
B4: STUDENT INFORMATION
B5: Evaluator Full Name | C5: Hamza Kazmi , Fahad Shafique
B6: Student ID | C6: FA23-BSE-063,021
B7: Section / Group | C7: A
B8: Date of Evaluation | C8: 26-4-26
B9: Device Model | C9: iphone 16e
B10: OS Version | C10: 26.3.1
B11: Network Conditions | C11: e.g. Campus WiFi / 4G
B13: APPLICATION PAIR SELECTION
B14: Choose ONE pair below. Circle / highlight your selection.
B15: Pair | C15: App 1 | D15: App 2 | E15: Primary Focus
B16: A | C16: WhatsApp | D16: Telegram | E16: Security, Usability, Reliability — closed vs open E2E encryption
B17: B | C17: Google Maps | D17: Apple Maps | E17: Performance, Compatibility, Usability — navigation design philosophies
B18: C | C18: Gmail | D18: Outlook Mobile | E18: Functional Suitability, Usability, Portability — email client comparison
B19: D | C19: Chrome Mobile | D19: Safari | E19: Performance, Compatibility, Security — native vs cross-platform
B20: E | C20: Spotify | D20: YouTube Music | E20: Performance, Reliability, Usability — streaming service quality
B21: F | C21: University App 1 | D21: University App 2 | E21: Full ISO 25010 analysis — choose any two university-context apps
B23: SELECTED PAIR — Fill in below
B24: Pair Letter | C24: App 1 Name | D24: App 2 Name
B25: E | C25: youtube music | D25: spotify
B27: APP VERSION METADATA
B28: Field | C28: App 1 | D28: Field | E28: App 2
B29: App Name | C29: youtube music | D29: App Name | E29: spotify
B30: Version Number | C30: 9.16.4 | D30: Version Number | E30: 9.1.42
B31: Platform | C31: iOS | D31: Platform | E31: iOS
B32: Min OS Required | C32: iOS 16.0 or later | D32: Min OS Required | E32: iOS 16.1 or later
B33: App Store Rating | C33: 4.7 | D33: App Store Rating | E33: 4.6
B34: Last Updated | C34: 22-4-26 | D34: Last Updated | E34: 23-4-26
B36: PRE-LAB CHECKLIST
B37: # | C37: Task | D37: When | E37: Status (✓ / ✗)
B38: 1 | C38: Read ISO/IEC 25010 Sections 1–4 overview | D38: Before Lab | E38: yes
B39: 2 | C39: Identify 3 daily apps & note one quality concern each | D39: Before Lab | E39: yes
B40: 3 | C40: Ensure both apps in chosen pair are installed on device | D40: Before Lab | E40: yes
B41: 4 | C41: Bring device with stopwatch / timer capability | D41: Lab Start | E41: yes
B42: 5 | C42: Have GitHub repository from Lab 1 open (week2/ folder) | D42: Lab Start | E42: yes
B43: 6 | C43: Install matplotlib: pip install matplotlib numpy | D43: Lab Start | E43: yes
B45: RATING SCALE QUICK REFERENCE
B46: Rating | C46: Label | D46: Definition | E46: Example Evidence
...

Sheet 📱 Structured — App 2
B1: App 2 Evaluation (Characteristics 1–8)
B2: 50 min | Individual — use your own device | Min. 3 observations per characteristic
B4: APP 2 METADATA
B5: App 2 Name | C5: spotify
B6: Version Number | C6: 9.1.42
B7: Device Model | C7: iphone 16e
B8: OS Version | C8: 26.3.1
B9: Evaluation Date | C9: 26-4-26
B10: Start Time | C10: 0.55694444
B12: C.3 CHARACTERISTIC 1 — Functional Suitability (Weight: 15%)
B13: Feature / Use Case to Test | C13: How to Test | D13: Pass / Fail / Partial | E13: Notes | F13: Evidence Screenshot
B14: Primary core function | C14: Play a song from search | D14: partial | E14: Works, but forced shuffle (mobile) and ads limit control | F14: =_xlfn.DISPIMG("ID_F74E38AC02A64138B969D959F579FF29",1) -> =DISPIMG("ID_F74E38AC02A64138B969D959F579FF29",1)
B15: Secondary feature 1 | C15: Create playlist | D15: pass | E15: Playlist creation is smooth and flexible | F15: =_xlfn.DISPIMG("ID_DE5FBFC30DA64EECB97E067CBCAC7A12",1) -> =DISPIMG("ID_DE5FBFC30DA64EECB97E067CBCAC7A12",1)
B16: Secondary feature 2 | C16: Try offline listening | D16: fail | E16: Requires premium subscription | F16: =_xlfn.DISPIMG("ID_6E48CFC86D324101AFF8125B18950D35",1) -> =DISPIMG("ID_6E48CFC86D324101AFF8125B18950D35",1)
B17: Error handling | C17: Search invalid input | D17: pass | E17: Shows recommendations or no results | F17: =_xlfn.DISPIMG("ID_F99D809F737C4D22A2AC81E55A1ED2FC",1) -> =DISPIMG("ID_F99D809F737C4D22A2AC81E55A1ED2FC",1)
B18: Edge case | C18: No internet / long playlist | D18: partial | E18: Cannot play offline; large playlists work but shuffle-only | F18: =_xlfn.DISPIMG("ID_E596CF20A0504B90B2FDC601EEAE6C9B",1) -> =DISPIMG("ID_E596CF20A0504B90B2FDC601EEAE6C9B",1)
B19: CHARACTERISTIC 1 RATING (1–5): | E19: 3 | F19: Justification:
B21: C.4 CHARACTERISTIC 2 — Performance Efficiency (Weight: 12%)
B22: Measurement | C22: Test Method | D22: Your Result | E22: Target (Rating 4+) | F22: Notes
B23: Cold start time | C23: Open app → fully loaded | D23: 2 sec | E23: < 3 seconds | F23: faster than yoiitube music
B24: Key operation 1 (primary) | C24: Search and play song | D24: 2 sec | E24: < 1 second | F24: fast response
B25: Key operation 2 (secondary) | C25: Open playlist | D25: 1 sec | E25: < 2 seconds | F25: smooth and optimized UI
B26: Battery drain | C26: Device Settings > Battery: % used in 10 min active use | D26: 2 percent | E26: < 3% | F26: efficient
B27: Slow network | C27: Switch to 4G only / poor signal — time key operation | D27: 3 sec | E27: < 5 seconds | F27: slow
B28: Data usage | C28: Device Settings > Data: MB used in 10 min active use | D28: 8MB | E28: < 10 MB | F28: lower than youtube music
B29: CHARACTERISTIC 2 RATING (1–5): | E29: 4 | F29: Justification:
B31: C.5 CHARACTERISTIC 3 — Compatibility (Weight: 10%)
B32: Compatibility Check | C32: What to Look For | D32: Result | E32: Evidence / Screenshot | F32: Notes
B33: Min OS version | C33: Check Play Store / App Store listing for minimum supported OS | D33: pass | E33: =_xlfn.DISPIMG("ID_5332393DA7E346EF84C6D46450F7C43A",1) -> =DISPIMG("ID_5332393DA7E346EF84C6D46450F7C43A",1) | F33: iOS 16.1
B34: Platform availability | C34: List all platforms: Android, iOS, Windows, macOS, Web, Linux | D34: pass | E34: =_xlfn.DISPIMG("ID_AA9758E08FA3498299261BB13476ED6C",1) -> =DISPIMG("ID_AA9758E08FA3498299261BB13476ED6C",1) | F34: available
B35: Cross-device sync | C35: Log in on a 2nd device — do data & settings appear? | D35: pass | F35: works with same account
B36: Content sharing (in) | C36: Can you share content FROM other apps INTO this app? | D36: partial | F36: Limited without third-party tools
B37: Content sharing (out) | C37: Can you share content FROM this app to 3+ other apps? | D37: pass | E37: =_xlfn.DISPIMG("ID_93C29DFCE3BB45C0BD9CF42B7423767A",1) -> =DISPIMG("ID_93C29DFCE3BB45C0BD9CF42B7423767A",1) | F37: Easy sharing via link, Instagram, WhatsApp
B38: Dark mode support | C38: Does the app respect your OS dark mode / accessibility settings? | D38: pass | F38: Default dark theme
B39: OS version compat. | C39: Any features broken on your specific OS version? | D39: pass | F39: No crashes or bugs observed
B40: CHARACTERISTIC 3 RATING (1–5): | E40: 5 | F40: Justification:
B42: C.6 CHARACTERISTIC 4 — Usability (Weight: 15%)
B43: Task | C43: Task Description | D43: Time (sec) | E43: Errors Made | F43: Completed?
B44: Task 1 | C44: Change setting | D44: 15 sec | E44: 0 | F44: yes
B45: Task 2 | C45: play song first time | D45: 8 | E45: 0 | F45: yes
...

Sheet App 1 (All 8)
B1: App 1 — All 8 ISO 25010 Characteristics
B2: Complete all 8 characteristics with rating AND evidence before moving to Exp D
B4: APP METADATA
B5: App Name | C5: ='📱 Structured — App 1'!C5 -> youtube music
B6: Version | C6: ='📱 Structured — App 1'!C6 -> 9.16.4
B7: Device | C7: ='📱 Structured — App 1'!C7 -> IPHONE 16e
B8: OS Version | C8: ='📱 Structured — App 1'!C8 -> 26.3.1
B9: Date | C9: ='📱 Structured — App 1'!C9 -> 26-4-26
B11: FULL EVALUATION CHECKLIST
B12: Quality Characteristic (ISO 25010) | C12: Rating (1–5) | D12: Weight | E12: Observations / Evidence (min. 2 specific points) | F12: Weighted Score
B13: 1. Functional Suitability | C13: 4 | D13: 15% | E13: [Hint: Does the app deliver all expected features correctly and completely? Test all advertised functions. Note any missing/broken features.] Observation 1: Observation 2: | F13: =C13*0.15 -> 0.6
B14: 2. Performance Efficiency | C14: 4 | D14: 12% | E14: [Hint: Response time, loading speed, battery & data usage. Record actual timings in seconds for at least 3 operations.] Observation 1: Observation 2: | F14: =C14*0.12 -> 0.48
B15: 3. Compatibility | C15: 4 | D15: 10% | E15: [Hint: Works correctly on different OS versions, screen sizes, browsers? Check platform availability listing. Test sharing.] Observation 1: Observation 2: | F15: =C15*0.1 -> 0.4
B16: 4. Usability | C16: 3 | D16: 15% | E16: [Hint: Ease of navigation, clarity of UI, onboarding experience? Complete 5 timed tasks without guidance.] Observation 1: Observation 2: | F16: =C16*0.15 -> 0.45
B17: 5. Reliability | C17: 4 | D17: 15% | E17: [Hint: App crashes, error handling, offline behavior, data integrity? Test Airplane Mode. Force-close mid-task.] Observation 1: Observation 2: | F17: =C17*0.15 -> 0.6
B18: 6. Security | C18: 4 | D18: 15% | E18: [Hint: Login security, data privacy, permissions, encryption? Check 2FA, permissions list, privacy policy, lockout behavior.] Observation 1: Observation 2: | F18: =C18*0.15 -> 0.6
B19: 7. Maintainability | C19: 4 | D19: 8% | E19: [Hint: Update frequency, bug fix speed, changelog quality? Review app store update history & release notes.] Observation 1: Observation 2: | F19: =C19*0.08 -> 0.32
B20: 8. Portability | C20: 4 | D20: 10% | E20: [Hint: Available on multiple platforms, cross-device sync? Test install/uninstall. Check dark mode & accessibility sync.] Observation 1: Observation 2: | F20: =C20*0.1 -> 0.4
B21: WEIGHTED TOTAL SCORE (out of 5.00) | F21: =SUM(F13:F20) -> 3.85
B23: SELF-CHECK BEFORE MOVING TO EXPERIMENT D
B24: Check | C24: Question
B25: Evidence | C25: Every rating has ≥1 specific observation in Notes? | E25: Each rating includes clear observations from testing | F25: Add at least one concrete observation before proceeding.
B26: Scale | C26: All ratings are whole numbers between 1 and 5? | E26: All ratings are whole numbers between 1 and 5 | F26: Revise any fractional or out-of-range ratings.
B27: Range | C27: Do your ratings span the full range (not all 4s and 5s)? | E27: Ratings range from 3 to 5 and are not all the same | F27: Re-examine 4s and 5s — look harder for deficiencies.
B28: Consistency | C28: Similar quality levels rated similarly across both apps? | E28: Ratings are consistent based on app performance | F28: If App 1 gets 5 for security, App 2 needs equivalent scrutiny.
B29: Independence | C29: Each characteristic rated independently (no brand bias)? | E29: Each characteristic is evaluated separately | F29: Revisit any ratings influenced by brand preference.

Sheet App 2 (All 8)
B1: App 2 — All 8 ISO 25010 Characteristics
B2: Complete all 8 characteristics with rating AND evidence before moving to Exp D
B4: APP METADATA
B5: App Name | C5: ='📱 Structured — App 2'!C5 -> spotify
B6: Version | C6: ='📱 Structured — App 2'!C6 -> 9.1.42
B7: Device | C7: ='📱 Structured — App 2'!C7 -> iphone 16e
B8: OS Version | C8: ='📱 Structured — App 2'!C8 -> 26.3.1
B9: Date | C9: ='📱 Structured — App 2'!C9 -> 26-4-26
B11: FULL EVALUATION CHECKLIST
B12: Quality Characteristic (ISO 25010) | C12: Rating (1–5) | D12: Weight | E12: Observations / Evidence (min. 2 specific points) | F12: Weighted Score
B13: 1. Functional Suitability | C13: 3 | D13: 15% | E13: [Hint: Does the app deliver all expected features correctly and completely? Test all advertised functions. Note any missing/broken features.] Observation 1: Observation 2: | F13: =C13*0.15 -> 0.45
B14: 2. Performance Efficiency | C14: 4 | D14: 12% | E14: [Hint: Response time, loading speed, battery & data usage. Record actual timings in seconds for at least 3 operations.] Observation 1: Observation 2: | F14: =C14*0.12 -> 0.48
B15: 3. Compatibility | C15: 5 | D15: 10% | E15: [Hint: Works correctly on different OS versions, screen sizes, browsers? Check platform availability listing. Test sharing.] Observation 1: Observation 2: | F15: =C15*0.1 -> 0.5
B16: 4. Usability | C16: 4 | D16: 15% | E16: [Hint: Ease of navigation, clarity of UI, onboarding experience? Complete 5 timed tasks without guidance.] Observation 1: Observation 2: | F16: =C16*0.15 -> 0.6
B17: 5. Reliability | C17: 4 | D17: 15% | E17: [Hint: App crashes, error handling, offline behavior, data integrity? Test Airplane Mode. Force-close mid-task.] Observation 1: Observation 2: | F17: =C17*0.15 -> 0.6
B18: 6. Security | C18: 3 | D18: 15% | E18: [Hint: Login security, data privacy, permissions, encryption? Check 2FA, permissions list, privacy policy, lockout behavior.] Observation 1: Observation 2: | F18: =C18*0.15 -> 0.45
B19: 7. Maintainability | C19: 4 | D19: 8% | E19: [Hint: Update frequency, bug fix speed, changelog quality? Review app store update history & release notes.] Observation 1: Observation 2: | F19: =C19*0.08 -> 0.32
B20: 8. Portability | C20: 5 | D20: 10% | E20: [Hint: Available on multiple platforms, cross-device sync? Test install/uninstall. Check dark mode & accessibility sync.] Observation 1: Observation 2: | F20: =C20*0.1 -> 0.5
B21: WEIGHTED TOTAL SCORE (out of 5.00) | F21: =SUM(F13:F20) -> 3.9
B23: SELF-CHECK BEFORE MOVING TO EXPERIMENT D
B24: Check | C24: Question
B25: Evidence | C25: Every rating has ≥1 specific observation in Notes? | E25: ='App 1 (All 8)'!E25 -> Each rating includes clear observations from testing | F25: Add at least one concrete observation before proceeding.
B26: Scale | C26: All ratings are whole numbers between 1 and 5? | E26: ='App 1 (All 8)'!E26 -> All ratings are whole numbers between 1 and 5 | F26: Revise any fractional or out-of-range ratings.
B27: Range | C27: Do your ratings span the full range (not all 4s and 5s)? | E27: ='App 1 (All 8)'!E27 -> Ratings range from 3 to 5 and are not all the same | F27: Re-examine 4s and 5s — look harder for deficiencies.
B28: Consistency | C28: Similar quality levels rated similarly across both apps? | E28: ='App 1 (All 8)'!E28 -> Ratings are consistent based on app performance | F28: If App 1 gets 5 for security, App 2 needs equivalent scrutiny.
B29: Independence | C29: Each characteristic rated independently (no brand bias)? | E29: ='App 1 (All 8)'!E29 -> Each characteristic is evaluated separately | F29: Revisit any ratings influenced by brand preference.

Sheet 📊 Comparative
B1: EXPERIMENT D — Comparative Analysis & Score Summary
B2: 25 min | Complete after both apps are fully evaluated
B4: APP IDENTIFICATION
C5: App 1 Name | E5: App 2 Name | G5: Evaluator
C6: youtube music | E6: spotify
B8: COMPARATIVE RATING SUMMARY TABLE
B9: Quality Characteristic | C9: Weight | D9: App 1 Rating | E9: App 2 Rating | F9: Gap (|A1–A2|) | G9: Better App
B10: 1. Functional Suitability | C10: 15% | D10: 4 | E10: 3 | F10: =ABS(D10-E10) -> 1 | G10: =IF(D10>E10,"App 1",IF(E10>D10,"App 2","Tied")) -> App 1
B11: 2. Performance Efficiency | C11: 12% | D11: 4 | E11: 4 | F11: =ABS(D11-E11) -> 0 | G11: =IF(D11>E11,"App 1",IF(E11>D11,"App 2","Tied")) -> Tied
B12: 3. Compatibility | C12: 10% | D12: 4 | E12: 5 | F12: =ABS(D12-E12) -> 1 | G12: =IF(D12>E12,"App 1",IF(E12>D12,"App 2","Tied")) -> App 2
B13: 4. Usability | C13: 15% | D13: 3 | E13: 4 | F13: =ABS(D13-E13) -> 1 | G13: =IF(D13>E13,"App 1",IF(E13>D13,"App 2","Tied")) -> App 2
B14: 5. Reliability | C14: 15% | D14: 4 | E14: 4 | F14: =ABS(D14-E14) -> 0 | G14: =IF(D14>E14,"App 1",IF(E14>D14,"App 2","Tied")) -> Tied
B15: 6. Security | C15: 15% | D15: 4 | E15: 3 | F15: =ABS(D15-E15) -> 1 | G15: =IF(D15>E15,"App 1",IF(E15>D15,"App 2","Tied")) -> App 1
B16: 7. Maintainability | C16: 8% | D16: 4 | E16: 4 | F16: =ABS(D16-E16) -> 0 | G16: =IF(D16>E16,"App 1",IF(E16>D16,"App 2","Tied")) -> Tied
B17: 8. Portability | C17: 10% | D17: 4 | E17: 5 | F17: =ABS(D17-E17) -> 1 | G17: =IF(D17>E17,"App 1",IF(E17>D17,"App 2","Tied")) -> App 2
D18: App 1 Weighted | E18: App 2 Weighted | F18: Margin
B19: WEIGHTED TOTAL SCORE | D19: =D10*0.15+D11*0.12+D12*0.1+D13*0.15+D14*0.15+D15*0.15+D16*0.08+D17*0.1 -> 3.85 | E19: =E10*0.15+E11*0.12+E12*0.1+E13*0.15+E14*0.15+E15*0.15+E16*0.08+E17*0.1 -> 3.9 | F19: =ABS(D19-E19) -> 0.05 | G19: =IF(D19>E19,"App 1 — "&C6," App 2 — "&C6) -> App 2 — youtube music
B21: PYTHON RADAR CHART — RATINGS REFERENCE
B22: Copy these values into your quality_analysis.py script
B23: Characteristic | C23: Weight | D23: App 1 Rating | E23: App 2 Rating | F23: App 1 Contrib. | G23: App 2 Contrib.
B24: 1. Functional Suitability | C24: 0.15 | D24: =D10 -> 4 | E24: =E10 -> 3 | F24: =D24*0.15 -> 0.6 | G24: =E24*0.15 -> 0.45
B25: 2. Performance Efficiency | C25: 0.12 | D25: =D11 -> 4 | E25: 4 | F25: =D25*0.12 -> 0.48 | G25: =E25*0.12 -> 0.48
B26: 3. Compatibility | C26: 0.1 | D26: =D12 -> 4 | E26: =E12 -> 5 | F26: =D26*0.1 -> 0.4 | G26: =E26*0.1 -> 0.5
B27: 4. Usability | C27: 0.15 | D27: =D13 -> 3 | E27: 4 | F27: =D27*0.15 -> 0.45 | G27: =E27*0.15 -> 0.6
B28: 5. Reliability | C28: 0.15 | D28: =D14 -> 4 | E28: 4 | F28: =D28*0.15 -> 0.6 | G28: =E28*0.15 -> 0.6
B29: 6. Security | C29: 0.15 | D29: =D15 -> 4 | E29: =E15 -> 3 | F29: =D29*0.15 -> 0.6 | G29: =E29*0.15 -> 0.45
B30: 7. Maintainability | C30: 0.08 | D30: =D16 -> 4 | E30: 4 | F30: =D30*0.08 -> 0.32 | G30: =E30*0.08 -> 0.32
B31: 8. Portability | C31: 0.1 | D31: =D17 -> 4 | E31: =E17 -> 5 | F31: =D31*0.1 -> 0.4 | G31: =E31*0.1 -> 0.5
B33: PYTHON ARRAY STRING (copy into quality_analysis.py)
B34: APP1_RATINGS = [R1, R2, R3, R4, R5, R6, R7, R8] ← replace with your Column D values above APP2_RATINGS = [R1, R2, R3, R4, R5, R6, R7, R8] ← replace with your Column E values above
B37: RADAR CHART INTERPRETATION GUIDE
B38: Analysis Question | E38: How to Answer | G38: Where in Report
B39: Which app has a larger polygon area? | E39: Larger area = higher overall quality score. Name it specifically. | G39: Comparative Analysis
B40: Where does App 1 extend further than App 2? | E40: These spokes = App 1's quality advantages. Name the characteristics. | G40: Comparative Analysis
B41: Are there any scores of 2 or below? | E41: Scores ≤2 = critical quality gaps requiring immediate attention. | G41: Recommendations
B42: Both apps score low on the same characteristic? | E42: May indicate an industry-wide challenge, not just one app's weakness. | G42: Comparative — trade-offs
B43: High scores correlating with low scores elsewhere? | E43: Look for security vs. usability or performance vs. functionality trade-offs. | G43: Comparative — trade-offs
B45: COMPARATIVE ANALYSIS WRITING SCAFFOLD
B46: Para 1 — Overall Scores
B47: [Hint: State both weighted scores and identify which app has higher overall quality. Include the margin. Template: '[App1] achieved a weighted quality score of [X]/5.00, compared to [App2]'s [Y]/5.00 — a margin of [Z] points.'] Your analysis here...
...

Sheet 💡 Recommendations
B1: SECTION 7 — Quality Improvement Recommendations
B2: 4 recommendations required: 2 per app | Each must follow the Recommendation Formula
B4: RECOMMENDATION FORMULA (must follow this structure)
B5: 📋 [App Name] should [specific action] in order to improve [characteristic] from its current rating of [X] to a target of [Y]. Currently, [specific observed deficiency]. This change would [specific user benefit].
B8: EXAMPLES — Good vs Bad Recommendations
B9: Quality | C9: Example Recommendation | D9: App | E9: Char. | F9: Why?
B10: ❌ BAD — Vague | C10: WhatsApp should improve security. | D10: WhatsApp | E10: Security | F10: No specific action, no mechanism, no evidence
B11: ❌ BAD — No evidence | C11: Telegram needs better reliability because it sometimes crashes. | D11: Telegram | E11: Reliability | F11: No specific observation, no target rating
B12: ✅ GOOD | C12: Telegram should add E2E encryption as default for all chats (not just Secret Chats) to improve Security from 4 to 5. Currently, standard chats are stored server-side. Enabling E2E by default gives users same confidentiality WhatsApp already provides. | D12: Telegram | E12: Security | F12: Specific action + evidence + benefit + target rating
B14: YOUR RECOMMENDATIONS — Fill in all shaded cells
B15: App 1 — Recommendation 1
B16: Field | C16: Your Answer
B17: App Name | C17: YouTube Music
B18: Specific Action | C18: Add offline download feature for free users (limited version
B19: Characteristic Improved | C19: Functional Suitability
B20: Current Rating | C20: 4
B21: Target Rating | C21: 5
B22: Specific Deficiency Observed | C22: Free users cannot download music for offline listening
B23: User Benefit | C23: Users can listen without internet, improving usability and experience
B24: Complete Recommendation (paragraph form) | C24: Introduce a limited offline download feature for free users (e.g., low-quality downloads or limited songs) to improve accessibility and overall functionality.
B27: App 1 — Recommendation 2
B28: Field | C28: Your Answer
B29: App Name | C29: YouTube Music
B30: Specific Action | C30: Improve navigation and settings layout
B31: Characteristic Improved | C31: Usability
B32: Current Rating | C32: 3
B33: Target Rating | C33: 4
B34: Specific Deficiency Observed | C34: Settings and help sections are hard to find
B35: User Benefit | C35: Easier navigation and faster task completion
B36: Complete Recommendation (paragraph form) | C36: Redesign the interface to make settings, help, and key features more visible and easier to access for users.
B39: App 2 — Recommendation 1
B40: Field | C40: Your Answer
B41: App Name | C41: Spotify
B42: Specific Action | C42: Add full 2FA security option for all users
B43: Characteristic Improved | C43: Security
B44: Current Rating | C44: 3
B45: Target Rating | C45: 5
B46: Specific Deficiency Observed | C46: Limited or no built-in two-factor authentication
B47: User Benefit | C47: Better account protection and data security
B48: Complete Recommendation (paragraph form) | C48: Implement a strong built-in two-factor authentication system (OTP or authenticator apps) to improve account security
...

Sheet 📄 Report Outline
B1: QUALITY ASSESSMENT REPORT — Section-by-Section Outline
B2: Use this as your PDF report writing guide | Minimum 600 words for Sections 6 & 7 combined
B4: Sec | C4: Title | D4: Required Content | E4: Target Length
B5: 1 | C5: Cover Information | D5: App names, version numbers, platform, OS version, evaluator name, student ID, date, pair letter. | E5: Half page
B6: 2 | C6: App Overviews | D6: One paragraph per app: primary purpose, target users, main features, app category. Note any relevant similarities or differences. | E6: ½–1 page
B7: 3 | C7: Evaluation Methodology | D7: Rating scale (1–5 Likert). How each characteristic was tested. Device & OS used. Duration per app. Tools used (timer, settings screenshots, etc.). | E7: ½ page
B8: 4 | C8: Completed Checklists | D8: Two fully completed checklist tables (one per app) with ratings, weights, and detailed observation notes. ALL 8 characteristics rated. | E8: 2 pages
B9: 5 | C9: Quality Profile Chart | D9: Your radar chart image generated by Python. Must be clearly labelled with app names and weighted scores in the legend. | E9: 1 page
B10: 6 | C10: Comparative Analysis | D10: 3–5 paragraphs comparing both apps. Must address: overall score comparison, top 3 quality gaps, at least 1 trade-off, recommendation with justification. | E10: 1–1.5 pages
B11: 7 | C11: Recommendations | D11: Exactly 2 specific, actionable recommendations per app = 4 total. Each must name the specific feature/mechanism & reference the characteristic improved. | E11: 1 page
B13: COMMON MISTAKES TO AVOID
B14: Mistake | C14: Problem | D14: Fix
B15: ⚠️ Rating Without Evidence | C15: 'It feels secure' is not evidence. | D15: For every rating ask: 'What did I specifically observe?'
B16: ⚠️ Confusing Characteristics | C16: Marking down Reliability when app is slow (that's Performance). | D16: Re-read each ISO 25010 definition before rating.
B17: ⚠️ Inflated Ratings (All 4s & 5s) | C17: No real-world app scores perfectly across all 8 characteristics. | D17: For every 4 or 5, spend 2 extra minutes looking for deficiencies.
B18: ⚠️ Ignoring Weights in Analysis | C18: Comparing raw counts of 4s/5s instead of weighted scores. | D18: Always calculate and compare weighted total scores.
B19: ⚠️ Inconsistent Testing Conditions | C19: App 1 on fast WiFi, App 2 on poor 4G — results meaningless. | D19: Both apps: same device, OS, day, network conditions.
B20: ⚠️ Vague Recommendations | C20: 'Improve security' gives developers nothing actionable. | D20: Every rec. names a specific feature/mechanism + target rating + benefit.
B21: ⚠️ Brand Bias | C21: Rating well-known brand higher due to reputation, not evidence. | D21: Cover app name when reviewing ratings — would you change any?

Sheet 🏆 Grading Rubric
B1: GRADED LAB TASK — Evaluation Rubric | Total: 15 Marks
B2: Individual Assessment | CLO-1 (P-2) + CLO-2 (P-3) | Submitted via LMS
B4: MARKS BREAKDOWN
B5: Criterion | C5: Marks | D5: Weight | E5: Excellent (90–100%) | F5: Good (75–89%) | G5: Satisfactory (60–74%)
B6: C1 — Evaluation Completeness | C6: 3 | D6: 20% | E6: Both apps, all 8 chars rated (1–5), whole numbers, weighted scores correct. | F6: 7 of 8 chars rated; minor calc error (<0.1 difference). | G6: 5–6 chars rated; weighted scores present but with errors.
B7: C2 — Evidence Quality | C7: 3 | D7: 20% | E7: Every rating: ≥2 specific observations. Performance: actual timings. Security: specific mechanisms. | F7: ≥6 ratings per app have specific obs. 1–2 vague. Performance present. | G7: Evidence inconsistent. 3–5 adequate. No performance measurements.
B8: C3 — Python Script & Radar Chart | C8: 2 | D8: 13% | E8: Script runs with student's actual ratings. Chart clearly labelled. PNG in GitHub week2/. | F8: Script runs but uses example ratings. Chart present in GitHub. | G8: Script needs minor edits. Chart exists. Not in correct week2/ folder.
B9: C4 — Comparative Analysis | C9: 3 | D9: 20% | E9: Weighted score comparison; top 3 gaps with practical explanation; ≥1 trade-off; recommendation with use-case. | F9: Score comparison + 2 gaps. Trade-offs mentioned. Recommendation present. | G9: Score comparison. 1 gap. No trade-offs. Recommendation without justification.
B10: C5 — Recommendation Specificity | C10: 2 | D10: 13% | E10: 4 recs (2/app). Each: specific mechanism, characteristic, current/target rating, user benefit. | F10: 3–4 recs. Most specific. 1–2 missing mechanism detail. Target rating not always stated. | G10: 2–3 recs. Mix of specific and vague. Chars referenced without current/target.
B11: C6 — Report Structure | C11: 1 | D11: 7% | E11: All 7 sections in correct order. Professional formatting. Radar chart embedded. Cover complete. | F11: 6 of 7 sections. Minor formatting. Cover mostly complete. Chart present. | G11: 5 of 7 sections. Sections out of order. Chart may be missing.
B12: C7 — GitHub & File Naming | C12: 1 | D12: 7% | E12: Files in week2/. Correct commit message. PDF named correctly. GitHub URL in LMS. On time. | F12: Files in correct location. Minor commit msg deviation. On time. | G12: Files in GitHub but wrong folder. PDF naming incorrect. On time.
B13: TOTAL MARKS | E13: =SUM(C6:C12) -> 15 | F13: / 15 marks
B15: GRADING SCALE
B16: Marks | C16: Grade | D16: Descriptor
B17: 14–15 | C17: A (Distinction) | D17: Excellent — professional quality evaluation, thorough evidence, insightful analysis, specific recommendations.
B18: 11–13 | C18: B (Merit) | D18: Good — all components present with adequate quality; minor gaps in evidence depth or analysis.
B19: 8–10 | C19: C (Pass) | D19: Satisfactory — meets basic requirements; noticeable gaps in evidence or analysis; recommendations may be vague.
B20: 5–7 | C20: D (Marginal) | D20: Borderline — significant effort but major requirements incomplete; evaluation substantially deficient.
B21: 0–4 | C21: F (Fail) | D21: Insufficient — critical requirements missing; evaluation not conducted properly or not submitted.
B23: INSTRUCTOR MARKING CHECKLIST
B24: # | C24: Check | F24: Yes / No | G24: Marks
B25: 1 | C25: Both apps evaluated with all 8 characteristics rated (1–5, whole numbers)
B26: 2 | C26: Weighted scores calculated and present for both apps
B27: 3 | C27: Every rating has at least 1 specific observation (not 'it feels good')
B28: 4 | C28: Performance ratings include actual measured timings (seconds)
B29: 5 | C29: Security ratings reference specific mechanisms (2FA, permissions, encryption)
B30: 6 | C30: quality_analysis.py in week2/ on GitHub with student's actual ratings (not examples)
B31: 7 | C31: Radar chart PNG in week2/ on GitHub, both apps labelled with scores
B32: 8 | C32: Comparative analysis compares weighted scores explicitly with numbers
B33: 9 | C33: At least 1 quality trade-off identified and explained in comparative analysis
B34: 10 | C34: 4 recommendations (2/app) each naming a specific mechanism
B35: 11 | C35: All 7 report sections present in submitted PDF
B36: 12 | C36: PDF named correctly and submitted to LMS before deadline

Sheet 📖 ISO 25010 Reference
B1: ISO 25010 Quick Reference Card | All 8 Quality Characteristics
B3: # | C3: Characteristic | D3: Sub-Characteristics | E3: Key Question | F3: Weight | G3: Test Approach
B4: 1 | C4: Functional Suitability | D4: Completeness, Correctness, Appropriateness | E4: Does it do what users need? | F4: 15% | G4: Feature checklist — Pass/Fail per advertised function. Test edge cases.
B5: 2 | C5: Performance Efficiency | D5: Time behaviour, Resource utilisation, Capacity | E5: Does it do it fast enough? | F5: 12% | G5: Stopwatch timings; device battery/data settings. Record actual numbers.
B6: 3 | C6: Compatibility | D6: Co-existence, Interoperability | E6: Does it work with other systems? | F6: 10% | G6: App store listing; cross-platform sync test; sharing test with 3+ apps.
B7: 4 | C7: Usability | D7: Learnability, Operability, Aesthetics, Accessibility | E7: Is it easy and pleasant to use? | F7: 15% | G7: 5-task usability test — timed, unguided, record errors.
B8: 5 | C8: Reliability | D8: Availability, Fault tolerance, Recoverability, Maturity | E8: Does it work consistently? | F8: 15% | G8: 10-min session; Airplane Mode test; force-close test; note crashes.
B9: 6 | C9: Security | D9: Confidentiality, Integrity, Authenticity, Accountability | E9: Is data and access protected? | F9: 15% | G9: HTTPS check; permissions list; 2FA; privacy policy review; lockout test.
B10: 7 | C10: Maintainability | D10: Modularity, Analysability, Modifiability, Testability | E10: Can it be changed/fixed easily? | F10: 8% | G10: Update history; changelog quality; open bug age; response to CVEs.
B11: 8 | C11: Portability | D11: Adaptability, Install ability, Replaceability | E11: Can it run in different environments? | F11: 10% | G11: Platform count; install/uninstall; cross-device sync; dark mode respect.
B13: CHARACTERISTIC TRADE-OFFS — Know Before You Rate
B14: Trade-off | C14: Example | F14: Implication
B15: Security vs. Usability | C15: 2FA improves security but adds login friction → lower usability score. | F15: Rate each independently. Note the trade-off in comparative analysis.
B16: Performance vs. Security | C16: Encryption adds CPU overhead → highly secure app may have slower response times. | F16: Do not penalize security for slower performance if encryption is the cause.
B17: Portability vs. Performance | C17: Cross-platform frameworks (React Native, Flutter) may perform worse than native. | F17: Document the platform context when rating performance.
B18: Reliability vs. Functionality | C18: Adding more features increases complexity → can reduce reliability score. | F18: A feature-rich app rated lower on reliability is an expected trade-off.
B20: RATING SCALE — 1–5 LIKERT
B21: Rating | C21: Label | D21: Definition | F21: Example Justification
B22: 5 | C22: Excellent | D22: Exceeds expectations. Fully & consistently satisfied. | F22: App launches <1s; 2FA enabled; zero crashes in 10-min session
B23: 4 | C23: Good | D23: Mostly satisfied. Minor issues, rarely noticeable. | F23: Occasional 2s load; settings menu slightly hard to find
B24: 3 | C24: Acceptable | D24: Partially satisfied. Noticeable but system remains usable. | F24: Crashes once per 10 min; offline shows stale data
B25: 2 | C25: Poor | D25: Mostly unsatisfied. Significant issues degrade quality. | F25: Crashes twice in 5 min; loading takes 8+ seconds
B26: 1 | C26: Unacceptable | D26: Critical failures. Characteristic essentially absent. | F26: Data wiped on restart; cannot perform primary purpose
